<?xml version="1.0"?>
<robot name="rover">
  <link name="base_link">
    <visual>
      <geometry>
        <box size="0.373800 0.472400 0.02"/>
      </geometry>
	  <origin rpy="0 0 0" xyz="0 0 0.1"/>
    </visual>
  </link>

  <link name="front_right_wheel">
    <visual>
      <geometry>
        <cylinder length="0.044450" radius="0.1"/>
      </geometry>
      <origin rpy="0 1.57075 0" xyz="0 0 0"/>
    </visual>
  </link>

  <link name="rear_right_wheel">
    <visual>
      <geometry>
        <cylinder length="0.044450" radius="0.1"/>
      </geometry>
      <origin rpy="0 1.57075 0" xyz="0 0 0"/>
    </visual>
  </link>

  <link name="front_left_wheel">
    <visual>
      <geometry>
        <cylinder length="0.044450" radius="0.1"/>
      </geometry>
      <origin rpy="0 1.57075 0" xyz="0 0 0"/>
    </visual>
  </link>

  <link name="rear_left_wheel">
    <visual>
      <geometry>
        <cylinder length="0.044450" radius="0.1"/>
      </geometry>
      <origin rpy="0 1.57075 0" xyz="0 0 0"/>
    </visual>
  </link>

  <joint name="fl_wheel_joint" type="continuous">
    <parent link="base_link"/>
    <child link="front_left_wheel"/>
    <origin rpy="0 0 0" xyz="-0.225 0.16 0.1"/>
    <axis xyz="1 0 0"/>
  </joint>

  <joint name="fr_wheel_joint" type="continuous">
    <parent link="base_link"/>
    <child link="front_right_wheel"/>
    <origin rpy="0 0 0" xyz="0.225 0.16 0.1"/>
    <axis xyz="1 0 0"/>
  </joint>

  <joint name="rl_wheel_joint" type="continuous">
    <parent link="base_link"/>
    <child link="rear_left_wheel"/>
    <origin rpy="0 0 0" xyz="-0.225 -0.16 0.1"/>
    <axis xyz="1 0 0"/>
  </joint>

 <joint name="rr_wheel_joint" type="continuous">
    <parent link="base_link"/>
    <child link="rear_right_wheel"/>
    <origin rpy="0 0 0" xyz="0.225 -0.16 0.1"/>
    <axis xyz="1 0 0"/>
  </joint>
</robot>